Workbook

Sheet LEEME
A1: Base de datos de eficiencia de producción. Planta de alimentos ilustrativa
A2: Naturaleza de los datos | B2: Sintéticos | C2: Datos simulados con semilla 20260917. No provienen de ninguna planta real ni de SAP. Sustituir por datos reales antes de cualquier decisión.
A3: Horizonte | B3: 104 semanas | C3: Semanas que inician lunes, del 2024-09-16 al 2026-09-07. Moneda: USD. Unidad de volumen: lbs.
A4: Estructura | B4: 8 líneas | C4: Cada línea es un 'activo' candidato para asignación de capacidad/capital. 832 registros línea-semana y 2185 eventos de paro.
A6: Convención de colores
A7: Texto azul | B7: Captura | C7: Dato de entrada; es la única celda que se reemplaza con datos reales.
A8: Texto negro | B8: Fórmula | C8: Cálculo en la misma hoja. No sobrescribir.
A9: Texto verde | B9: Vínculo | C9: Fórmula que trae datos de otra hoja. No sobrescribir.
A10: Relleno amarillo | B10: Supuesto clave | C10: Parámetro global editable (Parametros!N2:N4).
A12: Hojas
A13: Produccion_Semanal | B13: Tabla de hechos | C13: Una fila por línea y semana (tbl_produccion). Encabezados en fila 1, sin celdas combinadas; lista para pandas.read_excel(sheet_name='Produccion_Semanal').
A14: Eventos_Paro | B14: Bitácora | C14: Un evento de paro no planificado por fila (tbl_eventos). Alimenta Paro_No_Planificado_h por SUMIFS.
A15: Parametros | B15: Maestro | C15: Estándares por línea (tasa, costo de material, scrap estándar, precio, tarifa MO, capital empleado) y supuestos globales.
A16: Catalogo_Causas | B16: Maestro | C16: Causas de paro y su clasificación.
A17: Matriz_Retornos | B17: Serie pivote | C17: Semanas en filas, líneas en columnas; valor = Retorno_Semanal_Capital. Formato de entrada típico para un modelo de portafolio.
A18: Matriz_OEE | B18: Serie pivote | C18: Mismo formato con OEE semanal.
A19: Matriz_Margen_USD | B19: Serie pivote | C19: Mismo formato con margen de contribución semanal en USD.
A20: Control_Datos | B20: Validación | C20: Estadística descriptiva por línea y controles de integridad (conteo, conciliación de paros, duplicados).
A22: Definiciones clave
A23: Tiempo_Operativo_h | B23: Fórmula | C23: Horas_Programadas − Paro_Planificado_h − Paro_No_Planificado_h.
A24: Disponibilidad | B24: Fórmula | C24: Tiempo_Operativo_h / (Horas_Programadas − Paro_Planificado_h). El paro planificado no penaliza OEE.
A25: Rendimiento | B25: Fórmula | C25: Lbs_Totales / (Tasa_Estandar_lbs_h × Tiempo_Operativo_h). Sin tope de 100% para exponer tasas estándar mal cargadas.
A26: Calidad | B26: Fórmula | C26: Lbs_Buenas / Lbs_Totales.
A27: OEE | B27: Fórmula | C27: Disponibilidad × Rendimiento × Calidad.
A28: Costo_Perfeccion_USD | B28: Fórmula | C28: Lbs_Buenas × Costo_Material_Std_USD_lb (costo estándar sin scrap).
A29: Scrap_Estandar_USD | B29: Fórmula | C29: Costo_Perfeccion_USD × Factor_Scrap_Std.
A30: Costo_Prime_Std_USD | B30: Fórmula | C30: Perfección + scrap estándar = costo estándar del volumen de producto terminado.
A31: MUV_USD | B31: Fórmula | C31: Material_Real_USD − Costo_Prime_Std_USD. Positivo = desfavorable.
A32: Perdida_Abs_Real_USD | B32: Fórmula | C32: Scrap_Estandar_USD + MUV_USD.
A33: YTP_Pct | B33: Fórmula | C33: Perdida_Abs_Real_USD / Costo_Perfeccion_USD (yield loss to perfection).
A34: Costo_Conversion_USD | B34: Fórmula | C34: Mano de obra (con prima de horas extra) + energía + mantenimiento planificado y no planificado. Excluye depreciación y asignaciones.
... A36: Retorno_Semanal_Capital | B36: Fórmula | C36: Margen_Contribucion_USD / Capital_Empleado_USD. Serie de retorno por línea.
A38: Eventos sembrados para prueba
A39: L05 semana 2025-06-16 | B39: Falla | C39: Homogeneizador, 840 minutos (C01), scrap +3 pp y USD 18,000 de mantenimiento correctivo adicional.
A40: L07 semana 2026-02-09 | B40: Suministro | C40: Formadora-llenadora-selladora, 540 minutos por falta de empaque (C04).
A41: L03 semanas 2025-11-03 a 2025-12-15 | B41: MUV | C41: MUV desfavorable adicional de 3.5% sobre costo prime estándar (simula sustitución de ingrediente).
A42: L04 Salsa BBQ | B42: Estacionalidad | C42: Horas programadas y plan con estacionalidad de ±18% y pico hacia julio; demanda con variación semanal por línea de 5% a 15%.
A43: Calibración | B43: Precio y capital | C43: Precio neto calibrado a márgenes de contribución objetivo de 20% a 33% y capital empleado calibrado a retornos anuales de 18% a 38%. Ambos supuestos son ilustrativos.
A45: Limitaciones
A46: Capital empleado | B46: Constante | C46: Un valor fijo por línea en Parametros; en datos reales conviene saldo semanal o mensual de activo neto.
...

Sheet Produccion_Semanal
A1: Registro_ID | B1: Semana_Inicio | C1: Anio_Calendario | D1: Semana_Num | E1: Linea_ID | F1: Linea | G1: Horas_Programadas | H1: Paro_Planificado_h | I1: Paro_No_Planificado_h | J1: Tiempo_Operativo_h | K1: Lbs_Plan | L1: Lbs_Buenas | M1: Lbs_Scrap | N1: Lbs_Totales | O1: Tasa_Estandar_lbs_h | P1: Disponibilidad | Q1: Rendimiento | R1: Calidad | S1: OEE | T1: Cumplimiento_Plan | U1: Horas_MO | V1: HC | W1: Horas_Extra | X1: Pct_Horas_Extra | Y1: Lbs_por_Hora_MO | Z1: Costo_Perfeccion_USD | AA1: Scrap_Estandar_USD | AB1: Costo_Prime_Std_USD | AC1: Material_Real_USD | AD1: MUV_USD | AE1: Perdida_Abs_Real_USD | AF1: YTP_Pct | AG1: Costo_MO_USD | AH1: kWh | AI1: Costo_Energia_USD | AJ1: Mant_Planificado_USD | AK1: Mant_No_Planificado_USD | AL1: Costo_Conversion_USD | AM1: Costo_Conversion_USD_lb | AN1: Ingreso_Neto_USD | AO1: Margen_Contribucion_USD | AP1: Margen_Contribucion_Pct | AQ1: Capital_Empleado_USD | AR1: Retorno_Semanal_Capital
A2: L01-20240916 | B2: 45551 | C2: =TEXT(B2,"yyyy") -> 2024 | D2: =WEEKNUM(B2,2) -> 38 | E2: L01 | F2: =INDEX(Parametros!$B$2:$B$9,MATCH($E2,Parametros!$A$2:$A$9,0)) -> Ketchup botella | G2: 117.6 | H2: 10 | I2: =SUMIFS(Eventos_Paro!$J$2:$J$2186,Eventos_Paro!$D$2:$D$2186,$E2,Eventos_Paro!$B$2:$B$2186,$B2) -> 8.55 | J2: =G2-H2-I2 -> 99.05 | K2: 786425 | L2: 786669 | M2: 12143 | N2: =L2+M2 -> 798812 | O2: =INDEX(Parametros!$D$2:$D$9,MATCH($E2,Parametros!$A$2:$A$9,0)) -> 9000 | P2: =IF((G2-H2)>0,J2/(G2-H2),0) -> 0.92053903 | Q2: =IF(J2*O2>0,N2/(O2*J2),0) -> 0.89608166 | R2: =IF(N2>0,L2/N2,0) -> 0.98479868 | S2: =P2*Q2*R2 -> 0.81233891 | T2: =IF(K2>0,L2/K2,0) -> 1.0003103 | U2: 1876.6 | V2: 15 | W2: 112.6 | X2: =IF(U2>0,W2/U2,0) -> 0.060002132 | Y2: =IF(U2>0,L2/U2,0) -> 419.19908 | Z2: =L2*INDEX(Parametros!$E$2:$E$9,MATCH($E2,Parametros!$A$2:$A$9,0)) -> 330400.98 | AA2: =Z2*INDEX(Parametros!$F$2:$F$9,MATCH($E2,Parametros!$A$2:$A$9,0)) -> 6608.0196 | AB2: =Z2+AA2 -> 337009 | AC2: 346435.64 | AD2: =AC2-AB2 -> 9426.6404 | AE2: =AA2+AD2 -> 16034.66 | AF2: =IF(Z2>0,AE2/Z2,0) -> 0.048530909 | AG2: =(U2-W2)*INDEX(Parametros!$H$2:$H$9,MATCH($E2,Parametros!$A$2:$A$9,0))+W2*INDEX(Parametros!$H$2:$H$9,MATCH($E2,Parametros!$A$2:$A$9,0))*Parametros!$N$3 -> 60886.35 | AH2: 42570 | AI2: =AH2*Parametros!$N$2 -> 3916.44 | AJ2: 13921 | AK2: 3487 | AL2: =AG2+AI2+AJ2+AK2 -> 82210.79 | AM2: =IF(L2>0,AL2/L2,0) -> 0.10450493 | AN2: =L2*INDEX(Parametros!$G$2:$G$9,MATCH($E2,Parametros!$A$2:$A$9,0)) -> 558534.99 | AO2: =AN2-AC2-AL2 -> 129888.56 | AP2: =IF(AN2>0,AO2/AN2,0) -> 0.23255223 | AQ2: =INDEX(Parametros!$I$2:$I$9,MATCH($E2,Parametros!$A$2:$A$9,0)) -> 29300000 | AR2: =IF(AQ2>0,AO2/AQ2,0) -> 0.0044330567
A3: L02-20240916 | B3: 45551 | C3: =TEXT(B3,"yyyy") -> 2024 | D3: =WEEKNUM(B3,2) -> 38 | E3: L02 | F3: =INDEX(Parametros!$B$2:$B$9,MATCH($E3,Parametros!$A$2:$A$9,0)) -> Mayonesa frasco | G3: 130.5 | H3: 11.8 | I3: =SUMIFS(Eventos_Paro!$J$2:$J$2186,Eventos_Paro!$D$2:$D$2186,$E3,Eventos_Paro!$B$2:$B$2186,$B3) -> 0 | J3: =G3-H3-I3 -> 118.7 | K3: 626565 | L3: 650662 | M3: 22497 | N3: =L3+M3 -> 673159 | O3: =INDEX(Parametros!$D$2:$D$9,MATCH($E3,Parametros!$A$2:$A$9,0)) -> 6500 | P3: =IF((G3-H3)>0,J3/(G3-H3),0) -> 1 | Q3: =IF(J3*O3>0,N3/(O3*J3),0) -> 0.87247618 | R3: =IF(N3>0,L3/N3,0) -> 0.96657996 | S3: =P3*Q3*R3 -> 0.843318 | T3: =IF(K3>0,L3/K3,0) -> 1.0384589 | U3: 1770 | V3: 13 | W3: 73.5 | X3: =IF(U3>0,W3/U3,0) -> 0.041525424 | Y3: =IF(U3>0,L3/U3,0) -> 367.60565 | Z3: =L3*INDEX(Parametros!$E$2:$E$9,MATCH($E3,Parametros!$A$2:$A$9,0)) -> 396903.82 | AA3: =Z3*INDEX(Parametros!$F$2:$F$9,MATCH($E3,Parametros!$A$2:$A$9,0)) -> 9922.5955 | AB3: =Z3+AA3 -> 406826.42 | AC3: 408611.16 | AD3: =AC3-AB3 -> 1784.7445 | AE3: =AA3+AD3 -> 11707.34 | AF3: =IF(Z3>0,AE3/Z3,0) -> 0.029496667 | AG3: =(U3-W3)*INDEX(Parametros!$H$2:$H$9,MATCH($E3,Parametros!$A$2:$A$9,0))+W3*INDEX(Parametros!$H$2:$H$9,MATCH($E3,Parametros!$A$2:$A$9,0))*Parametros!$N$3 -> 56912.625 | AH3: 31949 | AI3: =AH3*Parametros!$N$2 -> 2939.308 | AJ3: 15149 | AK3: 0 | AL3: =AG3+AI3+AJ3+AK3 -> 75000.933 | AM3: =IF(L3>0,AL3/L3,0) -> 0.11526865 | AN3: =L3*INDEX(Parametros!$G$2:$G$9,MATCH($E3,Parametros!$A$2:$A$9,0)) -> 624635.52 | AO3: =AN3-AC3-AL3 -> 141023.43 | AP3: =IF(AN3>0,AO3/AN3,0) -> 0.22576914 | AQ3: =INDEX(Parametros!$I$2:$I$9,MATCH($E3,Parametros!$A$2:$A$9,0)) -> 29700000 | AR3: =IF(AQ3>0,AO3/AQ3,0) -> 0.0047482635
A4: L03-20240916 | B4: 45551 | C4: =TEXT(B4,"yyyy") -> 2024 | D4: =WEEKNUM(B4,2) -> 38 | E4: L03 | F4: =INDEX(Parametros!$B$2:$B$9,MATCH($E4,Parametros!$A$2:$A$9,0)) -> Aderezos vertibles | G4: 111.3 | H4: 11.5 | I4: =SUMIFS(Eventos_Paro!$J$2:$J$2186,Eventos_Paro!$D$2:$D$2186,$E4,Eventos_Paro!$B$2:$B$2186,$B4) -> 2.2833333 | J4: =G4-H4-I4 -> 97.516667 | K4: 421440 | L4: 411298 | M4: 16616 | N4: =L4+M4 -> 427914 | O4: =INDEX(Parametros!$D$2:$D$9,MATCH($E4,Parametros!$A$2:$A$9,0)) -> 5200 | P4: =IF((G4-H4)>0,J4/(G4-H4),0) -> 0.97712091 | Q4: =IF(J4*O4>0,N4/(O4*J4),0) -> 0.84386758 | R4: =IF(N4>0,L4/N4,0) -> 0.96116977 | S4: =P4*Q4*R4 -> 0.79254278 | T4: =IF(K4>0,L4/K4,0) -> 0.97593489 | U4: 1590.4 | V4: 13 | W4: 143.5 | X4: =IF(U4>0,W4/U4,0) -> 0.090228873 | Y4: =IF(U4>0,L4/U4,0) -> 258.61293 | Z4: =L4*INDEX(Parametros!$E$2:$E$9,MATCH($E4,Parametros!$A$2:$A$9,0)) -> 226213.9 | AA4: =Z4*INDEX(Parametros!$F$2:$F$9,MATCH($E4,Parametros!$A$2:$A$9,0)) -> 6786.417 | AB4: =Z4+AA4 -> 233000.32 | AC4: 240991.47 | AD4: =AC4-AB4 -> 7991.153 | AE4: =AA4+AD4 -> 14777.57 | AF4: =IF(Z4>0,AE4/Z4,0) -> 0.06532565 | AG4: =(U4-W4)*INDEX(Parametros!$H$2:$H$9,MATCH($E4,Parametros!$A$2:$A$9,0))+W4*INDEX(Parametros!$H$2:$H$9,MATCH($E4,Parametros!$A$2:$A$9,0))*Parametros!$N$3 -> 52357.725 | AH4: 21997 | AI4: =AH4*Parametros!$N$2 -> 2023.724 | AJ4: 12405 | AK4: 2011 | AL4: =AG4+AI4+AJ4+AK4 -> 68797.449 | AM4: =IF(L4>0,AL4/L4,0) -> 0.16726911 | AN4: =L4*INDEX(Parametros!$G$2:$G$9,MATCH($E4,Parametros!$A$2:$A$9,0)) -> 419523.96 | AO4: =AN4-AC4-AL4 -> 109735.04 | AP4: =IF(AN4>0,AO4/AN4,0) -> 0.26157038 | AQ4: =INDEX(Parametros!$I$2:$I$9,MATCH($E4,Parametros!$A$2:$A$9,0)) -> 19300000 | AR4: =IF(AQ4>0,AO4/AQ4,0) -> 0.0056857534
A5: L04-20240916 | B5: 45551 | C5: =TEXT(B5,"yyyy") -> 2024 | D5: =WEEKNUM(B5,2) -> 38 | E5: L04 | F5: =INDEX(Parametros!$B$2:$B$9,MATCH($E5,Parametros!$A$2:$A$9,0)) -> Salsa BBQ | G5: 92.3 | H5: 10.7 | I5: =SUMIFS(Eventos_Paro!$J$2:$J$2186,Eventos_Paro!$D$2:$D$2186,$E5,Eventos_Paro!$B$2:$B$2186,$B5) -> 2.5166667 | J5: =G5-H5-I5 -> 79.083333 | K5: 334647 | L5: 288993 | M5: 6406 | N5: =L5+M5 -> 295399 | O5: =INDEX(Parametros!$D$2:$D$9,MATCH($E5,Parametros!$A$2:$A$9,0)) -> 4800 | P5: =IF((G5-H5)>0,J5/(G5-H5),0) -> 0.9691585 | Q5: =IF(J5*O5>0,N5/(O5*J5),0) -> 0.77818493 | R5: =IF(N5>0,L5/N5,0) -> 0.97831408 | S5: =P5*Q5*R5 -> 0.73782935 | T5: =IF(K5>0,L5/K5,0) -> 0.86357565 | U5: 1027.4 | V5: 10 | W5: 104.4 | X5: =IF(U5>0,W5/U5,0) -> 0.10161573 | Y5: =IF(U5>0,L5/U5,0) -> 281.28577 | Z5: =L5*INDEX(Parametros!$E$2:$E$9,MATCH($E5,Parametros!$A$2:$A$9,0)) -> 167615.94 | AA5: =Z5*INDEX(Parametros!$F$2:$F$9,MATCH($E5,Parametros!$A$2:$A$9,0)) -> 4693.2463 | AB5: =Z5+AA5 -> 172309.19 | AC5: 174004.52 | AD5: =AC5-AB5 -> 1695.3337 | AE5: =AA5+AD5 -> 6388.58 | AF5: =IF(Z5>0,AE5/Z5,0) -> 0.038114394 | AG5: =(U5-W5)*INDEX(Parametros!$H$2:$H$9,MATCH($E5,Parametros!$A$2:$A$9,0))+W5*INDEX(Parametros!$H$2:$H$9,MATCH($E5,Parametros!$A$2:$A$9,0))*Parametros!$N$3 -> 34007.4 | AH5: 15689 | AI5: =AH5*Parametros!$N$2 -> 1443.388 | AJ5: 9783 | AK5: 2478 | AL5: =AG5+AI5+AJ5+AK5 -> 47711.788 | AM5: =IF(L5>0,AL5/L5,0) -> 0.16509669 | AN5: =L5*INDEX(Parametros!$G$2:$G$9,MATCH($E5,Parametros!$A$2:$A$9,0)) -> 283213.14 | AO5: =AN5-AC5-AL5 -> 61496.832 | AP5: =IF(AN5>0,AO5/AN5,0) -> 0.21713976 | AQ5: =INDEX(Parametros!$I$2:$I$9,MATCH($E5,Parametros!$A$2:$A$9,0)) -> 17000000 | AR5: =IF(AQ5>0,AO5/AQ5,0) -> 0.0036174607
A6: L05-20240916 | B6: 45551 | C6: =TEXT(B6,"yyyy") -> 2024 | D6: =WEEKNUM(B6,2) -> 38 | E6: L05 | F6: =INDEX(Parametros!$B$2:$B$9,MATCH($E6,Parametros!$A$2:$A$9,0)) -> Queso crema | G6: 123.9 | H6: 12.6 | I6: =SUMIFS(Eventos_Paro!$J$2:$J$2186,Eventos_Paro!$D$2:$D$2186,$E6,Eventos_Paro!$B$2:$B$2186,$B6) -> 10.516667 | J6: =G6-H6-I6 -> 100.78333 | K6: 343464 | L6: 308281 | M6: 15474 | N6: =L6+M6 -> 323755 | O6: =INDEX(Parametros!$D$2:$D$9,MATCH($E6,Parametros!$A$2:$A$9,0)) -> 3800 | P6: =IF((G6-H6)>0,J6/(G6-H6),0) -> 0.90551063 | Q6: =IF(J6*O6>0,N6/(O6*J6),0) -> 0.84536482 | R6: =IF(N6>0,L6/N6,0) -> 0.9522046 | S6: =P6*Q6*R6 -> 0.72890008 | T6: =IF(K6>0,L6/K6,0) -> 0.89756423 | U6: 2076 | V6: 16 | W6: 93.6 | X6: =IF(U6>0,W6/U6,0) -> 0.045086705 | Y6: =IF(U6>0,L6/U6,0) -> 148.49759 | Z6: =L6*INDEX(Parametros!$E$2:$E$9,MATCH($E6,Parametros!$A$2:$A$9,0)) -> 345274.72 | AA6: =Z6*INDEX(Parametros!$F$2:$F$9,MATCH($E6,Parametros!$A$2:$A$9,0)) -> 12084.615 | AB6: =Z6+AA6 -> 357359.34 | AC6: 358247.03 | AD6: =AC6-AB6 -> 887.6948 | AE6: =AA6+AD6 -> 12972.31 | AF6: =IF(Z6>0,AE6/Z6,0) -> 0.037570981 | AG6: =(U6-W6)*INDEX(Parametros!$H$2:$H$9,MATCH($E6,Parametros!$A$2:$A$9,0))+W6*INDEX(Parametros!$H$2:$H$9,MATCH($E6,Parametros!$A$2:$A$9,0))*Parametros!$N$3 -> 70052.4 | AH6: 16603 | AI6: =AH6*Parametros!$N$2 -> 1527.476 | AJ6: 21532 | AK6: 4932 | AL6: =AG6+AI6+AJ6+AK6 -> 98043.876 | AM6: =IF(L6>0,AL6/L6,0) -> 0.31803412 | AN6: =L6*INDEX(Parametros!$G$2:$G$9,MATCH($E6,Parametros!$A$2:$A$9,0)) -> 551822.99 | AO6: =AN6-AC6-AL6 -> 95532.084 | AP6: =IF(AN6>0,AO6/AN6,0) -> 0.17312088 | AQ6: =INDEX(Parametros!$I$2:$I$9,MATCH($E6,Parametros!$A$2:$A$9,0)) -> 33200000 | AR6: =IF(AQ6>0,AO6/AQ6,0) -> 0.0028774724
A7: L06-20240916 | B7: 45551 | C7: =TEXT(B7,"yyyy") -> 2024 | D7: =WEEKNUM(B7,2) -> 38 | E7: L06 | F7: =INDEX(Parametros!$B$2:$B$9,MATCH($E7,Parametros!$A$2:$A$9,0)) -> Crema de cacahuate | G7: 120.1 | H7: 12.1 | I7: =SUMIFS(Eventos_Paro!$J$2:$J$2186,Eventos_Paro!$D$2:$D$2186,$E7,Eventos_Paro!$B$2:$B$2186,$B7) -> 2.3833333 | J7: =G7-H7-I7 -> 105.61667 | K7: 368363 | L7: 366918 | M7: 8007 | N7: =L7+M7 -> 374925 | O7: =INDEX(Parametros!$D$2:$D$9,MATCH($E7,Parametros!$A$2:$A$9,0)) -> 4200 | P7: =IF((G7-H7)>0,J7/(G7-H7),0) -> 0.9779321 | Q7: =IF(J7*O7>0,N7/(O7*J7),0) -> 0.84520616 | R7: =IF(N7>0,L7/N7,0) -> 0.97864373 | S7: =P7*Q7*R7 -> 0.80890212 | T7: =IF(K7>0,L7/K7,0) -> 0.99607724 | U7: 1569.7 | V7: 12 | W7: 128.5 | X7: =IF(U7>0,W7/U7,0) -> 0.081862776 | Y7: =IF(U7>0,L7/U7,0) -> 233.7504 | Z7: =L7*INDEX(Parametros!$E$2:$E$9,MATCH($E7,Parametros!$A$2:$A$9,0)) -> 355910.46 | AA7: =Z7*INDEX(Parametros!$F$2:$F$9,MATCH($E7,Parametros!$A$2:$A$9,0)) -> 7830.0301 | AB7: =Z7+AA7 -> 363740.49 | AC7: 357872.2 | AD7: =AC7-AB7 -> -5868.2901 | AE7: =AA7+AD7 -> 1961.74 | AF7: =IF(Z7>0,AE7/Z7,0) -> 0.005511892 | AG7: =(U7-W7)*INDEX(Parametros!$H$2:$H$9,MATCH($E7,Parametros!$A$2:$A$9,0))+W7*INDEX(Parametros!$H$2:$H$9,MATCH($E7,Parametros!$A$2:$A$9,0))*Parametros!$N$3 -> 51469.425 | AH7: 20173 | AI7: =AH7*Parametros!$N$2 -> 1855.916 | AJ7: 11085 | AK7: 1753 | AL7: =AG7+AI7+AJ7+AK7 -> 66163.341 | AM7: =IF(L7>0,AL7/L7,0) -> 0.18032187 | AN7: =L7*INDEX(Parametros!$G$2:$G$9,MATCH($E7,Parametros!$A$2:$A$9,0)) -> 594407.16 | AO7: =AN7-AC7-AL7 -> 170371.62 | AP7: =IF(AN7>0,AO7/AN7,0) -> 0.28662444 | AQ7: =INDEX(Parametros!$I$2:$I$9,MATCH($E7,Parametros!$A$2:$A$9,0)) -> 28000000 | AR7: =IF(AQ7>0,AO7/AQ7,0) -> 0.0060847007
A8: L07-20240916 | B8: 45551 | C8: =TEXT(B8,"yyyy") -> 2024 | D8: =WEEKNUM(B8,2) -> 38 | E8: L07 | F8: =INDEX(Parametros!$B$2:$B$9,MATCH($E8,Parametros!$A$2:$A$9,0)) -> Porciones single serve | G8: 129.1 | H8: 12.2 | I8: =SUMIFS(Eventos_Paro!$J$2:$J$2186,Eventos_Paro!$D$2:$D$2186,$E8,Eventos_Paro!$B$2:$B$2186,$B8) -> 4.7666667 | J8: =G8-H8-I8 -> 112.13333 | K8: 246826 | L8: 223761 | M8: 14128 | N8: =L8+M8 -> 237889 | O8: =INDEX(Parametros!$D$2:$D$9,MATCH($E8,Parametros!$A$2:$A$9,0)) -> 2600 | P8: =IF((G8-H8)>0,J8/(G8-H8),0) -> 0.95922441 | Q8: =IF(J8*O8>0,N8/(O8*J8),0) -> 0.81595514 | R8: =IF(N8>0,L8/N8,0) -> 0.94061096 | S8: =P8*Q8*R8 -> 0.73620122 | T8: =IF(K8>0,L8/K8,0) -> 0.9065536 | U8: 2189.7 | V8: 16 | W8: 124.1 | X8: =IF(U8>0,W8/U8,0) -> 0.05667443 | Y8: =IF(U8>0,L8/U8,0) -> 102.18797 | Z8: =L8*INDEX(Parametros!$E$2:$E$9,MATCH($E8,Parametros!$A$2:$A$9,0)) -> 165583.14 | AA8: =Z8*INDEX(Parametros!$F$2:$F$9,MATCH($E8,Parametros!$A$2:$A$9,0)) -> 7451.2413 | AB8: =Z8+AA8 -> 173034.38 | AC8: 174953.68 | AD8: =AC8-AB8 -> 1919.2987 | AE8: =AA8+AD8 -> 9370.54 | AF8: =IF(Z8>0,AE8/Z8,0) -> 0.056591148 | AG8: =(U8-W8)*INDEX(Parametros!$H$2:$H$9,MATCH($E8,Parametros!$A$2:$A$9,0))+W8*INDEX(Parametros!$H$2:$H$9,MATCH($E8,Parametros!$A$2:$A$9,0))*Parametros!$N$3 -> 67552.5 | AH8: 12295 | AI8: =AH8*Parametros!$N$2 -> 1131.14 | AJ8: 11659 | AK8: 5197 | AL8: =AG8+AI8+AJ8+AK8 -> 85539.64 | AM8: =IF(L8>0,AL8/L8,0) -> 0.38228127 | AN8: =L8*INDEX(Parametros!$G$2:$G$9,MATCH($E8,Parametros!$A$2:$A$9,0)) -> 384868.92 | AO8: =AN8-AC8-AL8 -> 124375.6 | AP8: =IF(AN8>0,AO8/AN8,0) -> 0.32316353 | AQ8: =INDEX(Parametros!$I$2:$I$9,MATCH($E8,Parametros!$A$2:$A$9,0)) -> 15900000 | AR8: =IF(AQ8>0,AO8/AQ8,0) -> 0.0078223648
A9: L08-20240916 | B9: 45551 | C9: =TEXT(B9,"yyyy") -> 2024 | D9: =WEEKNUM(B9,2) -> 38 | E9: L08 | F9: =INDEX(Parametros!$B$2:$B$9,MATCH($E9,Parametros!$A$2:$A$9,0)) -> Salsas picantes | G9: 76 | H9: 12.5 | I9: =SUMIFS(Eventos_Paro!$J$2:$J$2186,Eventos_Paro!$D$2:$D$2186,$E9,Eventos_Paro!$B$2:$B$2186,$B9) -> 0.98333333 | J9: =G9-H9-I9 -> 62.516667 | K9: 154291 | L9: 164988 | M9: 6236 | N9: =L9+M9 -> 171224 | O9: =INDEX(Parametros!$D$2:$D$9,MATCH($E9,Parametros!$A$2:$A$9,0)) -> 3100 | P9: =IF((G9-H9)>0,J9/(G9-H9),0) -> 0.98451444 | Q9: =IF(J9*O9>0,N9/(O9*J9),0) -> 0.88350117 | R9: =IF(N9>0,L9/N9,0) -> 0.96357987 | S9: =P9*Q9*R9 -> 0.83814072 | T9: =IF(K9>0,L9/K9,0) -> 1.06933 | U9: 704.3 | V9: 9 | W9: 20.3 | X9: =IF(U9>0,W9/U9,0) -> 0.028822945 | Y9: =IF(U9>0,L9/U9,0) -> 234.25813 | Z9: =L9*INDEX(Parametros!$E$2:$E$9,MATCH($E9,Parametros!$A$2:$A$9,0)) -> 108892.08 | AA9: =Z9*INDEX(Parametros!$F$2:$F$9,MATCH($E9,Parametros!$A$2:$A$9,0)) -> 2831.1941 | AB9: =Z9+AA9 -> 111723.27 | AC9: 112020.41 | AD9: =AC9-AB9 -> 297.13592 | AE9: =AA9+AD9 -> 3128.33 | AF9: =IF(Z9>0,AE9/Z9,0) -> 0.028728719 | AG9: =(U9-W9)*INDEX(Parametros!$H$2:$H$9,MATCH($E9,Parametros!$A$2:$A$9,0))+W9*INDEX(Parametros!$H$2:$H$9,MATCH($E9,Parametros!$A$2:$A$9,0))*Parametros!$N$3 -> 22505.175 | AH9: 9174 | AI9: =AH9*Parametros!$N$2 -> 844.008 | AJ9: 5745 | AK9: 1023 | AL9: =AG9+AI9+AJ9+AK9 -> 30117.183 | AM9: =IF(L9>0,AL9/L9,0) -> 0.18254166 | AN9: =L9*INDEX(Parametros!$G$2:$G$9,MATCH($E9,Parametros!$A$2:$A$9,0)) -> 206235 | AO9: =AN9-AC9-AL9 -> 64097.407 | AP9: =IF(AN9>0,AO9/AN9,0) -> 0.31079791 | AQ9: =INDEX(Parametros!$I$2:$I$9,MATCH($E9,Parametros!$A$2:$A$9,0)) -> 13300000 | AR9: =IF(AQ9>0,AO9/AQ9,0) -> 0.0048193539
A10: L01-20240923 | B10: 45558 | C10: =TEXT(B10,"yyyy") -> 2024 | D10: =WEEKNUM(B10,2) -> 39 | E10: L01 | F10: =INDEX(Parametros!$B$2:$B$9,MATCH($E10,Parametros!$A$2:$A$9,0)) -> Ketchup botella | G10: 124.8 | H10: 8 | I10: =SUMIFS(Eventos_Paro!$J$2:$J$2186,Eventos_Paro!$D$2:$D$2186,$E10,Eventos_Paro!$B$2:$B$2186,$B10) -> 4.0666667 | J10: =G10-H10-I10 -> 112.73333 | K10: 849829 | L10: 904326 | M10: 12120 | N10: =L10+M10 -> 916446 | O10: =INDEX(Parametros!$D$2:$D$9,MATCH($E10,Parametros!$A$2:$A$9,0)) -> 9000 | P10: =IF((G10-H10)>0,J10/(G10-H10),0) -> 0.96518265 | Q10: =IF(J10*O10>0,N10/(O10*J10),0) -> 0.90325843 | R10: =IF(N10>0,L10/N10,0) -> 0.986775 | S10: =P10*Q10*R10 -> 0.86027968 | T10: =IF(K10>0,L10/K10,0) -> 1.064127 | U10: 1957.7 | V10: 14 | W10: 210.5 | X10: =IF(U10>0,W10/U10,0) -> 0.10752414 | Y10: =IF(U10>0,L10/U10,0) -> 461.93288 | Z10: =L10*INDEX(Parametros!$E$2:$E$9,MATCH($E10,Parametros!$A$2:$A$9,0)) -> 379816.92 | AA10: =Z10*INDEX(Parametros!$F$2:$F$9,MATCH($E10,Parametros!$A$2:$A$9,0)) -> 7596.3384 | AB10: =Z10+AA10 -> 387413.26 | AC10: 383035.54 | AD10: =AC10-AB10 -> -4377.7184 | AE10: =AA10+AD10 -> 3218.62 | AF10: =IF(Z10>0,AE10/Z10,0) -> 0.0084741354 | AG10: =(U10-W10)*INDEX(Parametros!$H$2:$H$9,MATCH($E10,Parametros!$A$2:$A$9,0))+W10*INDEX(Parametros!$H$2:$H$9,MATCH($E10,Parametros!$A$2:$A$9,0))*Parametros!$N$3 -> 64982.925 | AH10: 46656 | AI10: =AH10*Parametros!$N$2 -> 4292.352 | AJ10: 15794 | AK10: 2996 | AL10: =AG10+AI10+AJ10+AK10 -> 88065.277 | AM10: =IF(L10>0,AL10/L10,0) -> 0.097382224 | AN10: =L10*INDEX(Parametros!$G$2:$G$9,MATCH($E10,Parametros!$A$2:$A$9,0)) -> 642071.46 | AO10: =AN10-AC10-AL10 -> 170970.64 | AP10: =IF(AN10>0,AO10/AN10,0) -> 0.26627977 | AQ10: =INDEX(Parametros!$I$2:$I$9,MATCH($E10,Parametros!$A$2:$A$9,0)) -> 29300000 | AR10: =IF(AQ10>0,AO10/AQ10,0) -> 0.0058351755
A11: L02-20240923 | B11: 45558 | C11: =TEXT(B11,"yyyy") -> 2024 | D11: =WEEKNUM(B11,2) -> 39 | E11: L02 | F11: =INDEX(Parametros!$B$2:$B$9,MATCH($E11,Parametros!$A$2:$A$9,0)) -> Mayonesa frasco | G11: 119.3 | H11: 7.3 | I11: =SUMIFS(Eventos_Paro!$J$2:$J$2186,Eventos_Paro!$D$2:$D$2186,$E11,Eventos_Paro!$B$2:$B$2186,$B11) -> 5.0833333 | J11: =G11-H11-I11 -> 106.91667 | K11: 588542 | L11: 574691 | M11: 13212 | N11: =L11+M11 -> 587903 | O11: =INDEX(Parametros!$D$2:$D$9,MATCH($E11,Parametros!$A$2:$A$9,0)) -> 6500 | P11: =IF((G11-H11)>0,J11/(G11-H11),0) -> 0.9546131 | Q11: =IF(J11*O11>0,N11/(O11*J11),0) -> 0.84595431 | R11: =IF(N11>0,L11/N11,0) -> 0.9775269 | S11: =P11*Q11*R11 -> 0.78941071 | T11: =IF(K11>0,L11/K11,0) -> 0.97646557 | U11: 1496.5 | V11: 12 | W11: 64.9 | X11: =IF(U11>0,W11/U11,0) -> 0.043367858 | Y11: =IF(U11>0,L11/U11,0) -> 384.02339 | Z11: =L11*INDEX(Parametros!$E$2:$E$9,MATCH($E11,Parametros!$A$2:$A$9,0)) -> 350561.51 | AA11: =Z11*INDEX(Parametros!$F$2:$F$9,MATCH($E11,Parametros!$A$2:$A$9,0)) -> 8764.0377 | AB11: =Z11+AA11 -> 359325.55 | AC11: 361510.8 | AD11: =AC11-AB11 -> 2185.2522 | AE11: =AA11+AD11 -> 10949.29 | AF11: =IF(Z11>0,AE11/Z11,0) -> 0.031233577 | AG11: =(U11-W11)*INDEX(Parametros!$H$2:$H$9,MATCH($E11,Parametros!$A$2:$A$9,0))+W11*INDEX(Parametros!$H$2:$H$9,MATCH($E11,Parametros!$A$2:$A$9,0))*Parametros!$N$3 -> 48161.925 | AH11: 30337 | AI11: =AH11*Parametros!$N$2 -> 2791.004 | AJ11: 13156 | AK11: 5196 | AL11: =AG11+AI11+AJ11+AK11 -> 69304.929 | AM11: =IF(L11>0,AL11/L11,0) -> 0.12059512 | AN11: =L11*INDEX(Parametros!$G$2:$G$9,MATCH($E11,Parametros!$A$2:$A$9,0)) -> 551703.36 | AO11: =AN11-AC11-AL11 -> 120887.63 | AP11: =IF(AN11>0,AO11/AN11,0) -> 0.21911708 | AQ11: =INDEX(Parametros!$I$2:$I$9,MATCH($E11,Parametros!$A$2:$A$9,0)) -> 29700000 | AR11: =IF(AQ11>0,AO11/AQ11,0) -> 0.0040702906
A12: L03-20240923 | B12: 45558 | C12: =TEXT(B12,"yyyy") -> 2024 | D12: =WEEKNUM(B12,2) -> 39 | E12: L03 | F12: =INDEX(Parametros!$B$2:$B$9,MATCH($E12,Parametros!$A$2:$A$9,0)) -> Aderezos vertibles | G12: 118.7 | H12: 7.2 | I12: =SUMIFS(Eventos_Paro!$J$2:$J$2186,Eventos_Paro!$D$2:$D$2186,$E12,Eventos_Paro!$B$2:$B$2186,$B12) -> 2.0333333 | J12: =G12-H12-I12 -> 109.46667 | K12: 468732 | L12: 447940 | M12: 11761 | N12: =L12+M12 -> 459701 | O12: =INDEX(Parametros!$D$2:$D$9,MATCH($E12,Parametros!$A$2:$A$9,0)) -> 5200 | P12: =IF((G12-H12)>0,J12/(G12-H12),0) -> 0.98176383 | Q12: =IF(J12*O12>0,N12/(O12*J12),0) -> 0.80758866 | R12: =IF(N12>0,L12/N12,0) -> 0.97441598 | S12: =P12*Q12*R12 -> 0.77257675 | T12: =IF(K12>0,L12/K12,0) -> 0.95564203 | U12: 1549.2 | V12: 12 | W12: 124.8 | X12: =IF(U12>0,W12/U12,0) -> 0.080557707 | Y12: =IF(U12>0,L12/U12,0) -> 289.14278 | Z12: =L12*INDEX(Parametros!$E$2:$E$9,MATCH($E12,Parametros!$A$2:$A$9,0)) -> 246367 | AA12: =Z12*INDEX(Parametros!$F$2:$F$9,MATCH($E12,Parametros!$A$2:$A$9,0)) -> 7391.01 | AB12: =Z12+AA12 -> 253758.01 | AC12: 255226.51 | AD12: =AC12-AB12 -> 1468.5 | AE12: =AA12+AD12 -> 8859.51 | AF12: =IF(Z12>0,AE12/Z12,0) -> 0.03596062 | AG12: =(U12-W12)*INDEX(Parametros!$H$2:$H$9,MATCH($E12,Parametros!$A$2:$A$9,0))+W12*INDEX(Parametros!$H$2:$H$9,MATCH($E12,Parametros!$A$2:$A$9,0))*Parametros!$N$3 -> 50765.4 | AH12: 23860 | AI12: =AH12*Parametros!$N$2 -> 2195.12 | AJ12: 10793 | AK12: 1626 | AL12: =AG12+AI12+AJ12+AK12 -> 65379.52 | AM12: =IF(L12>0,AL12/L12,0) -> 0.14595598 | AN12: =L12*INDEX(Parametros!$G$2:$G$9,MATCH($E12,Parametros!$A$2:$A$9,0)) -> 456898.8 | AO12: =AN12-AC12-AL12 -> 136292.77 | AP12: =IF(AN12>0,AO12/AN12,0) -> 0.29829969 | AQ12: =INDEX(Parametros!$I$2:$I$9,MATCH($E12,Parametros!$A$2:$A$9,0)) -> 19300000 | AR12: =IF(AQ12>0,AO12/AQ12,0) -> 0.0070618016
A13: L04-20240923 | B13: 45558 | C13: =TEXT(B13,"yyyy") -> 2024 | D13: =WEEKNUM(B13,2) -> 39 | E13: L04 | F13: =INDEX(Parametros!$B$2:$B$9,MATCH($E13,Parametros!$A$2:$A$9,0)) -> Salsa BBQ | G13: 112.6 | H13: 6.6 | I13: =SUMIFS(Eventos_Paro!$J$2:$J$2186,Eventos_Paro!$D$2:$D$2186,$E13,Eventos_Paro!$B$2:$B$2186,$B13) -> 1.95 | J13: =G13-H13-I13 -> 104.05 | K13: 426358 | L13: 420721 | M13: 14121 | N13: =L13+M13 -> 434842 | O13: =INDEX(Parametros!$D$2:$D$9,MATCH($E13,Parametros!$A$2:$A$9,0)) -> 4800 | P13: =IF((G13-H13)>0,J13/(G13-H13),0) -> 0.98160377 | Q13: =IF(J13*O13>0,N13/(O13*J13),0) -> 0.87065914 | R13: =IF(N13>0,L13/N13,0) -> 0.96752614 | S13: =P13*Q13*R13 -> 0.82688876 | T13: =IF(K13>0,L13/K13,0) -> 0.98677872 | U13: 1464.9 | V13: 12 | W13: 113.7 | X13: =IF(U13>0,W13/U13,0) -> 0.07761622 | Y13: =IF(U13>0,L13/U13,0) -> 287.20117 | Z13: =L13*INDEX(Parametros!$E$2:$E$9,MATCH($E13,Parametros!$A$2:$A$9,0)) -> 244018.18 | AA13: =Z13*INDEX(Parametros!$F$2:$F$9,MATCH($E13,Parametros!$A$2:$A$9,0)) -> 6832.509 | AB13: =Z13+AA13 -> 250850.69 | AC13: 250583.53 | AD13: =AC13-AB13 -> -267.15904 | AE13: =AA13+AD13 -> 6565.35 | AF13: =IF(Z13>0,AE13/Z13,0) -> 0.026905167 | AG13: =(U13-W13)*INDEX(Parametros!$H$2:$H$9,MATCH($E13,Parametros!$A$2:$A$9,0))+W13*INDEX(Parametros!$H$2:$H$9,MATCH($E13,Parametros!$A$2:$A$9,0))*Parametros!$N$3 -> 47935.125 | AH13: 20543 | AI13: =AH13*Parametros!$N$2 -> 1889.956 | AJ13: 10107 | AK13: 2121 | AL13: =AG13+AI13+AJ13+AK13 -> 62053.081 | AM13: =IF(L13>0,AL13/L13,0) -> 0.14749224 | AN13: =L13*INDEX(Parametros!$G$2:$G$9,MATCH($E13,Parametros!$A$2:$A$9,0)) -> 412306.58 | AO13: =AN13-AC13-AL13 -> 99669.969 | AP13: =IF(AN13>0,AO13/AN13,0) -> 0.24173752 | AQ13: =INDEX(Parametros!$I$2:$I$9,MATCH($E13,Parametros!$A$2:$A$9,0)) -> 17000000 | AR13: =IF(AQ13>0,AO13/AQ13,0) -> 0.0058629394
... A833: L08-20260907 | B833: 46272 | C833: =TEXT(B833,"yyyy") -> 2026 | D833: =WEEKNUM(B833,2) -> 37 | E833: L08 | F833: =INDEX(Parametros!$B$2:$B$9,MATCH($E833,Parametros!$A$2:$A$9,0)) -> Salsas picantes | G833: 83.5 | H833: 8.4 | I833: =SUMIFS(Eventos_Paro!$J$2:$J$2186,Eventos_Paro!$D$2:$D$2186,$E833,Eventos_Paro!$B$2:$B$2186,$B833) -> 1.0833333 | J833: =G833-H833-I833 -> 74.016667 | K833: 180730 | L833: 195934 | M833: 4593 | N833: =L833+M833 -> 200527 | O833: =INDEX(Parametros!$D$2:$D$9,MATCH($E833,Parametros!$A$2:$A$9,0)) -> 3100 | P833: =IF((G833-H833)>0,J833/(G833-H833),0) -> 0.98557479 | Q833: =IF(J833*O833>0,N833/(O833*J833),0) -> 0.87394005 | R833: =IF(N833>0,L833/N833,0) -> 0.97709535 | S833: =P833*Q833*R833 -> 0.84160474 | T833: =IF(K833>0,L833/K833,0) -> 1.0841255 | U833: 701.6 | V833: 8 | W833: 33.6 | X833: =IF(U833>0,W833/U833,0) -> 0.047890536 | Y833: =IF(U833>0,L833/U833,0) -> 279.26739 | Z833: =L833*INDEX(Parametros!$E$2:$E$9,MATCH($E833,Parametros!$A$2:$A$9,0)) -> 129316.44 | AA833: =Z833*INDEX(Parametros!$F$2:$F$9,MATCH($E833,Parametros!$A$2:$A$9,0)) -> 3362.2274 | AB833: =Z833+AA833 -> 132678.67 | AC833: 133587.14 | AD833: =AC833-AB833 -> 908.47256 | AE833: =AA833+AD833 -> 4270.7 | AF833: =IF(Z833>0,AE833/Z833,0) -> 0.03302519 | AG833: =(U833-W833)*INDEX(Parametros!$H$2:$H$9,MATCH($E833,Parametros!$A$2:$A$9,0))+W833*INDEX(Parametros!$H$2:$H$9,MATCH($E833,Parametros!$A$2:$A$9,0))*Parametros!$N$3 -> 22629.6 | AH833: 9562 | AI833: =AH833*Parametros!$N$2 -> 879.704 | AJ833: 6089 | AK833: 541 | AL833: =AG833+AI833+AJ833+AK833 -> 30139.304 | AM833: =IF(L833>0,AL833/L833,0) -> 0.15382376 | AN833: =L833*INDEX(Parametros!$G$2:$G$9,MATCH($E833,Parametros!$A$2:$A$9,0)) -> 244917.5 | AO833: =AN833-AC833-AL833 -> 81191.056 | AP833: =IF(AN833>0,AO833/AN833,0) -> 0.33150369 | AQ833: =INDEX(Parametros!$I$2:$I$9,MATCH($E833,Parametros!$A$2:$A$9,0)) -> 13300000 | AR833: =IF(AQ833>0,AO833/AQ833,0) -> 0.0061045907

Sheet Parametros
A1: Linea_ID | B1: Linea | C1: Familia | D1: Tasa_Estandar_lbs_h | E1: Costo_Material_Std_USD_lb | F1: Factor_Scrap_Std | G1: Precio_Neto_USD_lb | H1: Tarifa_MO_USD_h | I1: Capital_Empleado_USD | J1: Horas_Programadas_Base_sem | K1: HC_Estandar | M1: Parametro_Global | N1: Valor | O1: Nota
A2: L01 | B2: Ketchup botella | C2: Condimentos | D2: 9000 | E2: 0.42 | F2: 0.02 | G2: 0.71 | H2: 31.5 | I2: 29300000 | J2: 120 | K2: 14 | M2: Tarifa_Energia_USD_kWh | N2: 0.092 | O2: Supuesto ilustrativo, no es tarifa real de un contrato
A3: L02 | B3: Mayonesa frasco | C3: Condimentos | D3: 6500 | E3: 0.61 | F3: 0.025 | G3: 0.96 | H3: 31.5 | I3: 29700000 | J3: 120 | K3: 13 | M3: Prima_Horas_Extra | N3: 1.5 | O3: Multiplicador sobre tarifa MO; supuesto ilustrativo
A4: L03 | B4: Aderezos vertibles | C4: Aderezos | D4: 5200 | E4: 0.55 | F4: 0.03 | G4: 1.02 | H4: 31.5 | I4: 19300000 | J4: 110 | K4: 12 | M4: Costo_Mant_NoPlan_USD_h_paro | N4: 850 | O4: Costo promedio por hora de paro no planificado; supuesto ilustrativo
A5: L04 | B5: Salsa BBQ | C5: Salsas | D5: 4800 | E5: 0.58 | F5: 0.028 | G5: 0.98 | H5: 31.5 | I5: 17000000 | J5: 100 | K5: 11
A6: L05 | B6: Queso crema | C6: Lácteos untables | D6: 3800 | E6: 1.12 | F6: 0.035 | G6: 1.79 | H6: 33 | I6: 33200000 | J6: 120 | K6: 15
A7: L06 | B7: Crema de cacahuate | C7: Untables | D7: 4200 | E7: 0.97 | F7: 0.022 | G7: 1.62 | H7: 31.5 | I7: 28000000 | J7: 110 | K7: 12
A8: L07 | B8: Porciones single serve | C8: Porciones | D8: 2600 | E8: 0.74 | F8: 0.045 | G8: 1.72 | H8: 30 | I8: 15900000 | J8: 120 | K8: 16
A9: L08 | B9: Salsas picantes | C9: Salsas | D9: 3100 | E9: 0.66 | F9: 0.026 | G9: 1.25 | H9: 31.5 | I9: 13300000 | J9: 96 | K9: 9

Sheet Catalogo_Causas
A1: Causa_ID | B1: Causa | C1: Clasificacion
A2: C01 | B2: Falla mecánica | C2: Operacional
A3: C02 | B3: Falla eléctrica / control | C3: Operacional
A4: C03 | B4: Cambio de formato excedido | C4: Operacional
A5: C04 | B5: Falta de material de empaque | C5: Material / suministro
A6: C05 | B6: Falta de materia prima | C6: Material / suministro
A7: C06 | B7: Retención de calidad | C7: Calidad
A8: C07 | B8: Limpieza no programada (CIP) | C8: Calidad
A9: C08 | B9: Falta de personal | C9: Personal
A10: C09 | B10: Falla de servicios (vapor/amoniaco/aire) | C10: Servicios

Sheet Eventos_Paro
A1: Evento_ID | B1: Semana_Inicio | C1: Fecha_Evento | D1: Linea_ID | E1: Activo | F1: Causa_ID | G1: Causa | H1: Clasificacion | I1: Minutos_Paro | J1: Horas_Paro
A2: EV00001 | B2: 45551 | C2: 45551 | D2: L01 | E2: Etiquetadora | F2: C02 | G2: =INDEX(Catalogo_Causas!$B$2:$B$10,MATCH(F2,Catalogo_Causas!$A$2:$A$10,0)) -> Falla eléctrica / control | H2: =INDEX(Catalogo_Causas!$C$2:$C$10,MATCH(F2,Catalogo_Causas!$A$2:$A$10,0)) -> Operacional | I2: 123 | J2: =I2/60 -> 2.05
A3: EV00002 | B3: 45551 | C3: 45551 | D3: L03 | E3: Llenadora | F3: C04 | G3: =INDEX(Catalogo_Causas!$B$2:$B$10,MATCH(F3,Catalogo_Causas!$A$2:$A$10,0)) -> Falta de material de empaque | H3: =INDEX(Catalogo_Causas!$C$2:$C$10,MATCH(F3,Catalogo_Causas!$A$2:$A$10,0)) -> Material / suministro | I3: 48 | J3: =I3/60 -> 0.8
A4: EV00003 | B4: 45551 | C4: 45551 | D4: L05 | E4: Homogeneizador | F4: C01 | G4: =INDEX(Catalogo_Causas!$B$2:$B$10,MATCH(F4,Catalogo_Causas!$A$2:$A$10,0)) -> Falla mecánica | H4: =INDEX(Catalogo_Causas!$C$2:$C$10,MATCH(F4,Catalogo_Causas!$A$2:$A$10,0)) -> Operacional | I4: 26 | J4: =I4/60 -> 0.43333333
A5: EV00004 | B5: 45551 | C5: 45551 | D5: L06 | E5: Molino de tostado | F5: C02 | G5: =INDEX(Catalogo_Causas!$B$2:$B$10,MATCH(F5,Catalogo_Causas!$A$2:$A$10,0)) -> Falla eléctrica / control | H5: =INDEX(Catalogo_Causas!$C$2:$C$10,MATCH(F5,Catalogo_Causas!$A$2:$A$10,0)) -> Operacional | I5: 30 | J5: =I5/60 -> 0.5
A6: EV00005 | B6: 45551 | C6: 45551 | D6: L06 | E6: Molino de tostado | F6: C05 | G6: =INDEX(Catalogo_Causas!$B$2:$B$10,MATCH(F6,Catalogo_Causas!$A$2:$A$10,0)) -> Falta de materia prima | H6: =INDEX(Catalogo_Causas!$C$2:$C$10,MATCH(F6,Catalogo_Causas!$A$2:$A$10,0)) -> Material / suministro | I6: 113 | J6: =I6/60 -> 1.8833333
A7: EV00006 | B7: 45551 | C7: 45552 | D7: L05 | E7: Llenadora de tinas | F7: C03 | G7: =INDEX(Catalogo_Causas!$B$2:$B$10,MATCH(F7,Catalogo_Causas!$A$2:$A$10,0)) -> Cambio de formato excedido | H7: =INDEX(Catalogo_Causas!$C$2:$C$10,MATCH(F7,Catalogo_Causas!$A$2:$A$10,0)) -> Operacional | I7: 96 | J7: =I7/60 -> 1.6
A8: EV00007 | B8: 45551 | C8: 45552 | D8: L07 | E8: Formadora-llenadora-selladora | F8: C03 | G8: =INDEX(Catalogo_Causas!$B$2:$B$10,MATCH(F8,Catalogo_Causas!$A$2:$A$10,0)) -> Cambio de formato excedido | H8: =INDEX(Catalogo_Causas!$C$2:$C$10,MATCH(F8,Catalogo_Causas!$A$2:$A$10,0)) -> Operacional | I8: 92 | J8: =I8/60 -> 1.5333333
A9: EV00008 | B9: 45551 | C9: 45552 | D9: L08 | E9: Molino | F9: C02 | G9: =INDEX(Catalogo_Causas!$B$2:$B$10,MATCH(F9,Catalogo_Causas!$A$2:$A$10,0)) -> Falla eléctrica / control | H9: =INDEX(Catalogo_Causas!$C$2:$C$10,MATCH(F9,Catalogo_Causas!$A$2:$A$10,0)) -> Operacional | I9: 28 | J9: =I9/60 -> 0.46666667
A10: EV00009 | B10: 45551 | C10: 45553 | D10: L01 | E10: Taponadora | F10: C05 | G10: =INDEX(Catalogo_Causas!$B$2:$B$10,MATCH(F10,Catalogo_Causas!$A$2:$A$10,0)) -> Falta de materia prima | H10: =INDEX(Catalogo_Causas!$C$2:$C$10,MATCH(F10,Catalogo_Causas!$A$2:$A$10,0)) -> Material / suministro | I10: 137 | J10: =I10/60 -> 2.2833333
A11: EV00010 | B11: 45551 | C11: 45553 | D11: L01 | E11: Etiquetadora | F11: C02 | G11: =INDEX(Catalogo_Causas!$B$2:$B$10,MATCH(F11,Catalogo_Causas!$A$2:$A$10,0)) -> Falla eléctrica / control | H11: =INDEX(Catalogo_Causas!$C$2:$C$10,MATCH(F11,Catalogo_Causas!$A$2:$A$10,0)) -> Operacional | I11: 79 | J11: =I11/60 -> 1.3166667
A12: EV00011 | B12: 45551 | C12: 45553 | D12: L03 | E12: Etiquetadora | F12: C04 | G12: =INDEX(Catalogo_Causas!$B$2:$B$10,MATCH(F12,Catalogo_Causas!$A$2:$A$10,0)) -> Falta de material de empaque | H12: =INDEX(Catalogo_Causas!$C$2:$C$10,MATCH(F12,Catalogo_Causas!$A$2:$A$10,0)) -> Material / suministro | I12: 69 | J12: =I12/60 -> 1.15
A13: EV00012 | B13: 45551 | C13: 45553 | D13: L05 | E13: Homogeneizador | F13: C01 | G13: =INDEX(Catalogo_Causas!$B$2:$B$10,MATCH(F13,Catalogo_Causas!$A$2:$A$10,0)) -> Falla mecánica | H13: =INDEX(Catalogo_Causas!$C$2:$C$10,MATCH(F13,Catalogo_Causas!$A$2:$A$10,0)) -> Operacional | I13: 52 | J13: =I13/60 -> 0.86666667
... A2186: EV02185 | B2186: 46272 | C2186: 46277 | D2186: L08 | E2186: Etiquetadora | F2186: C03 | G2186: =INDEX(Catalogo_Causas!$B$2:$B$10,MATCH(F2186,Catalogo_Causas!$A$2:$A$10,0)) -> Cambio de formato excedido | H2186: =INDEX(Catalogo_Causas!$C$2:$C$10,MATCH(F2186,Catalogo_Causas!$A$2:$A$10,0)) -> Operacional | I2186: 41 | J2186: =I2186/60 -> 0.68333333

Sheet Matriz_Retornos
A1: Semana_Inicio | B1: L01 | C1: L02 | D1: L03 | E1: L04 | F1: L05 | G1: L06 | H1: L07 | I1: L08
A2: 45551 | B2: =SUMIFS(Produccion_Semanal!$AR$2:$AR$833,Produccion_Semanal!$E$2:$E$833,B$1,Produccion_Semanal!$B$2:$B$833,$A2) -> 0.0044330567 | C2: =SUMIFS(Produccion_Semanal!$AR$2:$AR$833,Produccion_Semanal!$E$2:$E$833,C$1,Produccion_Semanal!$B$2:$B$833,$A2) -> 0.0047482635 | D2: =SUMIFS(Produccion_Semanal!$AR$2:$AR$833,Produccion_Semanal!$E$2:$E$833,D$1,Produccion_Semanal!$B$2:$B$833,$A2) -> 0.0056857534 | E2: =SUMIFS(Produccion_Semanal!$AR$2:$AR$833,Produccion_Semanal!$E$2:$E$833,E$1,Produccion_Semanal!$B$2:$B$833,$A2) -> 0.0036174607 | F2: =SUMIFS(Produccion_Semanal!$AR$2:$AR$833,Produccion_Semanal!$E$2:$E$833,F$1,Produccion_Semanal!$B$2:$B$833,$A2) -> 0.0028774724 | G2: =SUMIFS(Produccion_Semanal!$AR$2:$AR$833,Produccion_Semanal!$E$2:$E$833,G$1,Produccion_Semanal!$B$2:$B$833,$A2) -> 0.0060847007 | H2: =SUMIFS(Produccion_Semanal!$AR$2:$AR$833,Produccion_Semanal!$E$2:$E$833,H$1,Produccion_Semanal!$B$2:$B$833,$A2) -> 0.0078223648 | I2: =SUMIFS(Produccion_Semanal!$AR$2:$AR$833,Produccion_Semanal!$E$2:$E$833,I$1,Produccion_Semanal!$B$2:$B$833,$A2) -> 0.0048193539
A3: 45558 | B3: =SUMIFS(Produccion_Semanal!$AR$2:$AR$833,Produccion_Semanal!$E$2:$E$833,B$1,Produccion_Semanal!$B$2:$B$833,$A3) -> 0.0058351755 | C3: =SUMIFS(Produccion_Semanal!$AR$2:$AR$833,Produccion_Semanal!$E$2:$E$833,C$1,Produccion_Semanal!$B$2:$B$833,$A3) -> 0.0040702906 | D3: =SUMIFS(Produccion_Semanal!$AR$2:$AR$833,Produccion_Semanal!$E$2:$E$833,D$1,Produccion_Semanal!$B$2:$B$833,$A3) -> 0.0070618016 | E3: =SUMIFS(Produccion_Semanal!$AR$2:$AR$833,Produccion_Semanal!$E$2:$E$833,E$1,Produccion_Semanal!$B$2:$B$833,$A3) -> 0.0058629394 | F3: =SUMIFS(Produccion_Semanal!$AR$2:$AR$833,Produccion_Semanal!$E$2:$E$833,F$1,Produccion_Semanal!$B$2:$B$833,$A3) -> 0.0028768137 | G3: =SUMIFS(Produccion_Semanal!$AR$2:$AR$833,Produccion_Semanal!$E$2:$E$833,G$1,Produccion_Semanal!$B$2:$B$833,$A3) -> 0.0063310759 | H3: =SUMIFS(Produccion_Semanal!$AR$2:$AR$833,Produccion_Semanal!$E$2:$E$833,H$1,Produccion_Semanal!$B$2:$B$833,$A3) -> 0.0063713302 | I3: =SUMIFS(Produccion_Semanal!$AR$2:$AR$833,Produccion_Semanal!$E$2:$E$833,I$1,Produccion_Semanal!$B$2:$B$833,$A3) -> 0.0071955367
A4: 45565 | B4: =SUMIFS(Produccion_Semanal!$AR$2:$AR$833,Produccion_Semanal!$E$2:$E$833,B$1,Produccion_Semanal!$B$2:$B$833,$A4) -> 0.005294283 | C4: =SUMIFS(Produccion_Semanal!$AR$2:$AR$833,Produccion_Semanal!$E$2:$E$833,C$1,Produccion_Semanal!$B$2:$B$833,$A4) -> 0.0045636957 | D4: =SUMIFS(Produccion_Semanal!$AR$2:$AR$833,Produccion_Semanal!$E$2:$E$833,D$1,Produccion_Semanal!$B$2:$B$833,$A4) -> 0.006752798 | E4: =SUMIFS(Produccion_Semanal!$AR$2:$AR$833,Produccion_Semanal!$E$2:$E$833,E$1,Produccion_Semanal!$B$2:$B$833,$A4) -> 0.0044253039 | F4: =SUMIFS(Produccion_Semanal!$AR$2:$AR$833,Produccion_Semanal!$E$2:$E$833,F$1,Produccion_Semanal!$B$2:$B$833,$A4) -> 0.0051808633 | G4: =SUMIFS(Produccion_Semanal!$AR$2:$AR$833,Produccion_Semanal!$E$2:$E$833,G$1,Produccion_Semanal!$B$2:$B$833,$A4) -> 0.0049311971 | H4: =SUMIFS(Produccion_Semanal!$AR$2:$AR$833,Produccion_Semanal!$E$2:$E$833,H$1,Produccion_Semanal!$B$2:$B$833,$A4) -> 0.0088584546 | I4: =SUMIFS(Produccion_Semanal!$AR$2:$AR$833,Produccion_Semanal!$E$2:$E$833,I$1,Produccion_Semanal!$B$2:$B$833,$A4) -> 0.0086154686
A5: 45572 | B5: =SUMIFS(Produccion_Semanal!$AR$2:$AR$833,Produccion_Semanal!$E$2:$E$833,B$1,Produccion_Semanal!$B$2:$B$833,$A5) -> 0.0055325985 | C5: =SUMIFS(Produccion_Semanal!$AR$2:$AR$833,Produccion_Semanal!$E$2:$E$833,C$1,Produccion_Semanal!$B$2:$B$833,$A5) -> 0.0047098307 | D5: =SUMIFS(Produccion_Semanal!$AR$2:$AR$833,Produccion_Semanal!$E$2:$E$833,D$1,Produccion_Semanal!$B$2:$B$833,$A5) -> 0.0071235902 | E5: =SUMIFS(Produccion_Semanal!$AR$2:$AR$833,Produccion_Semanal!$E$2:$E$833,E$1,Produccion_Semanal!$B$2:$B$833,$A5) -> 0.0035666381 | F5: =SUMIFS(Produccion_Semanal!$AR$2:$AR$833,Produccion_Semanal!$E$2:$E$833,F$1,Produccion_Semanal!$B$2:$B$833,$A5) -> 0.0039790509 | G5: =SUMIFS(Produccion_Semanal!$AR$2:$AR$833,Produccion_Semanal!$E$2:$E$833,G$1,Produccion_Semanal!$B$2:$B$833,$A5) -> 0.0055437445 | H5: =SUMIFS(Produccion_Semanal!$AR$2:$AR$833,Produccion_Semanal!$E$2:$E$833,H$1,Produccion_Semanal!$B$2:$B$833,$A5) -> 0.0079581069 | I5: =SUMIFS(Produccion_Semanal!$AR$2:$AR$833,Produccion_Semanal!$E$2:$E$833,I$1,Produccion_Semanal!$B$2:$B$833,$A5) -> 0.0074474768
A6: 45579 | B6: =SUMIFS(Produccion_Semanal!$AR$2:$AR$833,Produccion_Semanal!$E$2:$E$833,B$1,Produccion_Semanal!$B$2:$B$833,$A6) -> 0.0054106712 | C6: =SUMIFS(Produccion_Semanal!$AR$2:$AR$833,Produccion_Semanal!$E$2:$E$833,C$1,Produccion_Semanal!$B$2:$B$833,$A6) -> 0.0038691613 | D6: =SUMIFS(Produccion_Semanal!$AR$2:$AR$833,Produccion_Semanal!$E$2:$E$833,D$1,Produccion_Semanal!$B$2:$B$833,$A6) -> 0.0072624818 | E6: =SUMIFS(Produccion_Semanal!$AR$2:$AR$833,Produccion_Semanal!$E$2:$E$833,E$1,Produccion_Semanal!$B$2:$B$833,$A6) -> 0.0047545541 | F6: =SUMIFS(Produccion_Semanal!$AR$2:$AR$833,Produccion_Semanal!$E$2:$E$833,F$1,Produccion_Semanal!$B$2:$B$833,$A6) -> 0.0032401755 | G6: =SUMIFS(Produccion_Semanal!$AR$2:$AR$833,Produccion_Semanal!$E$2:$E$833,G$1,Produccion_Semanal!$B$2:$B$833,$A6) -> 0.0058571586 | H6: =SUMIFS(Produccion_Semanal!$AR$2:$AR$833,Produccion_Semanal!$E$2:$E$833,H$1,Produccion_Semanal!$B$2:$B$833,$A6) -> 0.0073462035 | I6: =SUMIFS(Produccion_Semanal!$AR$2:$AR$833,Produccion_Semanal!$E$2:$E$833,I$1,Produccion_Semanal!$B$2:$B$833,$A6) -> 0.0067501045
A7: 45586 | B7: =SUMIFS(Produccion_Semanal!$AR$2:$AR$833,Produccion_Semanal!$E$2:$E$833,B$1,Produccion_Semanal!$B$2:$B$833,$A7) -> 0.0061462281 | C7: =SUMIFS(Produccion_Semanal!$AR$2:$AR$833,Produccion_Semanal!$E$2:$E$833,C$1,Produccion_Semanal!$B$2:$B$833,$A7) -> 0.0046801207 | D7: =SUMIFS(Produccion_Semanal!$AR$2:$AR$833,Produccion_Semanal!$E$2:$E$833,D$1,Produccion_Semanal!$B$2:$B$833,$A7) -> 0.0048777584 | E7: =SUMIFS(Produccion_Semanal!$AR$2:$AR$833,Produccion_Semanal!$E$2:$E$833,E$1,Produccion_Semanal!$B$2:$B$833,$A7) -> 0.0036149991 | F7: =SUMIFS(Produccion_Semanal!$AR$2:$AR$833,Produccion_Semanal!$E$2:$E$833,F$1,Produccion_Semanal!$B$2:$B$833,$A7) -> 0.0028133322 | G7: =SUMIFS(Produccion_Semanal!$AR$2:$AR$833,Produccion_Semanal!$E$2:$E$833,G$1,Produccion_Semanal!$B$2:$B$833,$A7) -> 0.0057373629 | H7: =SUMIFS(Produccion_Semanal!$AR$2:$AR$833,Produccion_Semanal!$E$2:$E$833,H$1,Produccion_Semanal!$B$2:$B$833,$A7) -> 0.0067926132 | I7: =SUMIFS(Produccion_Semanal!$AR$2:$AR$833,Produccion_Semanal!$E$2:$E$833,I$1,Produccion_Semanal!$B$2:$B$833,$A7) -> 0.0061801194
A8: 45593 | B8: =SUMIFS(Produccion_Semanal!$AR$2:$AR$833,Produccion_Semanal!$E$2:$E$833,B$1,Produccion_Semanal!$B$2:$B$833,$A8) -> 0.0048217984 | C8: =SUMIFS(Produccion_Semanal!$AR$2:$AR$833,Produccion_Semanal!$E$2:$E$833,C$1,Produccion_Semanal!$B$2:$B$833,$A8) -> 0.0044572322 | D8: =SUMIFS(Produccion_Semanal!$AR$2:$AR$833,Produccion_Semanal!$E$2:$E$833,D$1,Produccion_Semanal!$B$2:$B$833,$A8) -> 0.0056282843 | E8: =SUMIFS(Produccion_Semanal!$AR$2:$AR$833,Produccion_Semanal!$E$2:$E$833,E$1,Produccion_Semanal!$B$2:$B$833,$A8) -> 0.0061607102 | F8: =SUMIFS(Produccion_Semanal!$AR$2:$AR$833,Produccion_Semanal!$E$2:$E$833,F$1,Produccion_Semanal!$B$2:$B$833,$A8) -> 0.0033823086 | G8: =SUMIFS(Produccion_Semanal!$AR$2:$AR$833,Produccion_Semanal!$E$2:$E$833,G$1,Produccion_Semanal!$B$2:$B$833,$A8) -> 0.0058060311 | H8: =SUMIFS(Produccion_Semanal!$AR$2:$AR$833,Produccion_Semanal!$E$2:$E$833,H$1,Produccion_Semanal!$B$2:$B$833,$A8) -> 0.007499873 | I8: =SUMIFS(Produccion_Semanal!$AR$2:$AR$833,Produccion_Semanal!$E$2:$E$833,I$1,Produccion_Semanal!$B$2:$B$833,$A8) -> 0.0068256811
A9: 45600 | B9: =SUMIFS(Produccion_Semanal!$AR$2:$AR$833,Produccion_Semanal!$E$2:$E$833,B$1,Produccion_Semanal!$B$2:$B$833,$A9) -> 0.0050442391 | C9: =SUMIFS(Produccion_Semanal!$AR$2:$AR$833,Produccion_Semanal!$E$2:$E$833,C$1,Produccion_Semanal!$B$2:$B$833,$A9) -> 0.0041948055 | D9: =SUMIFS(Produccion_Semanal!$AR$2:$AR$833,Produccion_Semanal!$E$2:$E$833,D$1,Produccion_Semanal!$B$2:$B$833,$A9) -> 0.0064550239 | E9: =SUMIFS(Produccion_Semanal!$AR$2:$AR$833,Produccion_Semanal!$E$2:$E$833,E$1,Produccion_Semanal!$B$2:$B$833,$A9) -> 0.0054714915 | F9: =SUMIFS(Produccion_Semanal!$AR$2:$AR$833,Produccion_Semanal!$E$2:$E$833,F$1,Produccion_Semanal!$B$2:$B$833,$A9) -> 0.0037923583 | G9: =SUMIFS(Produccion_Semanal!$AR$2:$AR$833,Produccion_Semanal!$E$2:$E$833,G$1,Produccion_Semanal!$B$2:$B$833,$A9) -> 0.0069644273 | H9: =SUMIFS(Produccion_Semanal!$AR$2:$AR$833,Produccion_Semanal!$E$2:$E$833,H$1,Produccion_Semanal!$B$2:$B$833,$A9) -> 0.0035104473 | I9: =SUMIFS(Produccion_Semanal!$AR$2:$AR$833,Produccion_Semanal!$E$2:$E$833,I$1,Produccion_Semanal!$B$2:$B$833,$A9) -> 0.0060777559
A10: 45607 | B10: =SUMIFS(Produccion_Semanal!$AR$2:$AR$833,Produccion_Semanal!$E$2:$E$833,B$1,Produccion_Semanal!$B$2:$B$833,$A10) -> 0.0056365422 | C10: =SUMIFS(Produccion_Semanal!$AR$2:$AR$833,Produccion_Semanal!$E$2:$E$833,C$1,Produccion_Semanal!$B$2:$B$833,$A10) -> 0.0047702182 | D10: =SUMIFS(Produccion_Semanal!$AR$2:$AR$833,Produccion_Semanal!$E$2:$E$833,D$1,Produccion_Semanal!$B$2:$B$833,$A10) -> 0.0082826638 | E10: =SUMIFS(Produccion_Semanal!$AR$2:$AR$833,Produccion_Semanal!$E$2:$E$833,E$1,Produccion_Semanal!$B$2:$B$833,$A10) -> 0.0046850117 | F10: =SUMIFS(Produccion_Semanal!$AR$2:$AR$833,Produccion_Semanal!$E$2:$E$833,F$1,Produccion_Semanal!$B$2:$B$833,$A10) -> 0.0037933689 | G10: =SUMIFS(Produccion_Semanal!$AR$2:$AR$833,Produccion_Semanal!$E$2:$E$833,G$1,Produccion_Semanal!$B$2:$B$833,$A10) -> 0.0059106761 | H10: =SUMIFS(Produccion_Semanal!$AR$2:$AR$833,Produccion_Semanal!$E$2:$E$833,H$1,Produccion_Semanal!$B$2:$B$833,$A10) -> 0.0050753147 | I10: =SUMIFS(Produccion_Semanal!$AR$2:$AR$833,Produccion_Semanal!$E$2:$E$833,I$1,Produccion_Semanal!$B$2:$B$833,$A10) -> 0.0051294374
A11: 45614 | B11: =SUMIFS(Produccion_Semanal!$AR$2:$AR$833,Produccion_Semanal!$E$2:$E$833,B$1,Produccion_Semanal!$B$2:$B$833,$A11) -> 0.0049745973 | C11: =SUMIFS(Produccion_Semanal!$AR$2:$AR$833,Produccion_Semanal!$E$2:$E$833,C$1,Produccion_Semanal!$B$2:$B$833,$A11) -> 0.0045249172 | D11: =SUMIFS(Produccion_Semanal!$AR$2:$AR$833,Produccion_Semanal!$E$2:$E$833,D$1,Produccion_Semanal!$B$2:$B$833,$A11) -> 0.0074023888 | E11: =SUMIFS(Produccion_Semanal!$AR$2:$AR$833,Produccion_Semanal!$E$2:$E$833,E$1,Produccion_Semanal!$B$2:$B$833,$A11) -> 0.0036643537 | F11: =SUMIFS(Produccion_Semanal!$AR$2:$AR$833,Produccion_Semanal!$E$2:$E$833,F$1,Produccion_Semanal!$B$2:$B$833,$A11) -> 0.0038504658 | G11: =SUMIFS(Produccion_Semanal!$AR$2:$AR$833,Produccion_Semanal!$E$2:$E$833,G$1,Produccion_Semanal!$B$2:$B$833,$A11) -> 0.0063275111 | H11: =SUMIFS(Produccion_Semanal!$AR$2:$AR$833,Produccion_Semanal!$E$2:$E$833,H$1,Produccion_Semanal!$B$2:$B$833,$A11) -> 0.0075697136 | I11: =SUMIFS(Produccion_Semanal!$AR$2:$AR$833,Produccion_Semanal!$E$2:$E$833,I$1,Produccion_Semanal!$B$2:$B$833,$A11) -> 0.0054376044
A12: 45621 | B12: =SUMIFS(Produccion_Semanal!$AR$2:$AR$833,Produccion_Semanal!$E$2:$E$833,B$1,Produccion_Semanal!$B$2:$B$833,$A12) -> 0.0055289576 | C12: =SUMIFS(Produccion_Semanal!$AR$2:$AR$833,Produccion_Semanal!$E$2:$E$833,C$1,Produccion_Semanal!$B$2:$B$833,$A12) -> 0.0041285231 | D12: =SUMIFS(Produccion_Semanal!$AR$2:$AR$833,Produccion_Semanal!$E$2:$E$833,D$1,Produccion_Semanal!$B$2:$B$833,$A12) -> 0.0046258032 | E12: =SUMIFS(Produccion_Semanal!$AR$2:$AR$833,Produccion_Semanal!$E$2:$E$833,E$1,Produccion_Semanal!$B$2:$B$833,$A12) -> 0.0042656244 | F12: =SUMIFS(Produccion_Semanal!$AR$2:$AR$833,Produccion_Semanal!$E$2:$E$833,F$1,Produccion_Semanal!$B$2:$B$833,$A12) -> 0.0039685298 | G12: =SUMIFS(Produccion_Semanal!$AR$2:$AR$833,Produccion_Semanal!$E$2:$E$833,G$1,Produccion_Semanal!$B$2:$B$833,$A12) -> 0.0047144626 | H12: =SUMIFS(Produccion_Semanal!$AR$2:$AR$833,Produccion_Semanal!$E$2:$E$833,H$1,Produccion_Semanal!$B$2:$B$833,$A12) -> 0.0086364103 | I12: =SUMIFS(Produccion_Semanal!$AR$2:$AR$833,Produccion_Semanal!$E$2:$E$833,I$1,Produccion_Semanal!$B$2:$B$833,$A12) -> 0.006876925
A13: 45628 | B13: =SUMIFS(Produccion_Semanal!$AR$2:$AR$833,Produccion_Semanal!$E$2:$E$833,B$1,Produccion_Semanal!$B$2:$B$833,$A13) -> 0.0046550832 | C13: =SUMIFS(Produccion_Semanal!$AR$2:$AR$833,Produccion_Semanal!$E$2:$E$833,C$1,Produccion_Semanal!$B$2:$B$833,$A13) -> 0.0033310664 | D13: =SUMIFS(Produccion_Semanal!$AR$2:$AR$833,Produccion_Semanal!$E$2:$E$833,D$1,Produccion_Semanal!$B$2:$B$833,$A13) -> 0.0072924785 | E13: =SUMIFS(Produccion_Semanal!$AR$2:$AR$833,Produccion_Semanal!$E$2:$E$833,E$1,Produccion_Semanal!$B$2:$B$833,$A13) -> 0.0050358586 | F13: =SUMIFS(Produccion_Semanal!$AR$2:$AR$833,Produccion_Semanal!$E$2:$E$833,F$1,Produccion_Semanal!$B$2:$B$833,$A13) -> 0.0034375962 | G13: =SUMIFS(Produccion_Semanal!$AR$2:$AR$833,Produccion_Semanal!$E$2:$E$833,G$1,Produccion_Semanal!$B$2:$B$833,$A13) -> 0.0054713002 | H13: =SUMIFS(Produccion_Semanal!$AR$2:$AR$833,Produccion_Semanal!$E$2:$E$833,H$1,Produccion_Semanal!$B$2:$B$833,$A13) -> 0.0093554351 | I13: =SUMIFS(Produccion_Semanal!$AR$2:$AR$833,Produccion_Semanal!$E$2:$E$833,I$1,Produccion_Semanal!$B$2:$B$833,$A13) -> 0.0072012757
... A105: 46272 | B105: =SUMIFS(Produccion_Semanal!$AR$2:$AR$833,Produccion_Semanal!$E$2:$E$833,B$1,Produccion_Semanal!$B$2:$B$833,$A105) -> 0.0059295871 | C105: =SUMIFS(Produccion_Semanal!$AR$2:$AR$833,Produccion_Semanal!$E$2:$E$833,C$1,Produccion_Semanal!$B$2:$B$833,$A105) -> 0.0043152179 | D105: =SUMIFS(Produccion_Semanal!$AR$2:$AR$833,Produccion_Semanal!$E$2:$E$833,D$1,Produccion_Semanal!$B$2:$B$833,$A105) -> 0.0086072616 | E105: =SUMIFS(Produccion_Semanal!$AR$2:$AR$833,Produccion_Semanal!$E$2:$E$833,E$1,Produccion_Semanal!$B$2:$B$833,$A105) -> 0.0050679109 | F105: =SUMIFS(Produccion_Semanal!$AR$2:$AR$833,Produccion_Semanal!$E$2:$E$833,F$1,Produccion_Semanal!$B$2:$B$833,$A105) -> 0.0055744189 | G105: =SUMIFS(Produccion_Semanal!$AR$2:$AR$833,Produccion_Semanal!$E$2:$E$833,G$1,Produccion_Semanal!$B$2:$B$833,$A105) -> 0.0060320587 | H105: =SUMIFS(Produccion_Semanal!$AR$2:$AR$833,Produccion_Semanal!$E$2:$E$833,H$1,Produccion_Semanal!$B$2:$B$833,$A105) -> 0.0055665545 | I105: =SUMIFS(Produccion_Semanal!$AR$2:$AR$833,Produccion_Semanal!$E$2:$E$833,I$1,Produccion_Semanal!$B$2:$B$833,$A105) -> 0.0061045907

Sheet Matriz_OEE
A1: Semana_Inicio | B1: L01 | C1: L02 | D1: L03 | E1: L04 | F1: L05 | G1: L06 | H1: L07 | I1: L08
A2: 45551 | B2: =SUMIFS(Produccion_Semanal!$S$2:$S$833,Produccion_Semanal!$E$2:$E$833,B$1,Produccion_Semanal!$B$2:$B$833,$A2) -> 0.81233891 | C2: =SUMIFS(Produccion_Semanal!$S$2:$S$833,Produccion_Semanal!$E$2:$E$833,C$1,Produccion_Semanal!$B$2:$B$833,$A2) -> 0.843318 | D2: =SUMIFS(Produccion_Semanal!$S$2:$S$833,Produccion_Semanal!$E$2:$E$833,D$1,Produccion_Semanal!$B$2:$B$833,$A2) -> 0.79254278 | E2: =SUMIFS(Produccion_Semanal!$S$2:$S$833,Produccion_Semanal!$E$2:$E$833,E$1,Produccion_Semanal!$B$2:$B$833,$A2) -> 0.73782935 | F2: =SUMIFS(Produccion_Semanal!$S$2:$S$833,Produccion_Semanal!$E$2:$E$833,F$1,Produccion_Semanal!$B$2:$B$833,$A2) -> 0.72890008 | G2: =SUMIFS(Produccion_Semanal!$S$2:$S$833,Produccion_Semanal!$E$2:$E$833,G$1,Produccion_Semanal!$B$2:$B$833,$A2) -> 0.80890212 | H2: =SUMIFS(Produccion_Semanal!$S$2:$S$833,Produccion_Semanal!$E$2:$E$833,H$1,Produccion_Semanal!$B$2:$B$833,$A2) -> 0.73620122 | I2: =SUMIFS(Produccion_Semanal!$S$2:$S$833,Produccion_Semanal!$E$2:$E$833,I$1,Produccion_Semanal!$B$2:$B$833,$A2) -> 0.83814072
A3: 45558 | B3: =SUMIFS(Produccion_Semanal!$S$2:$S$833,Produccion_Semanal!$E$2:$E$833,B$1,Produccion_Semanal!$B$2:$B$833,$A3) -> 0.86027968 | C3: =SUMIFS(Produccion_Semanal!$S$2:$S$833,Produccion_Semanal!$E$2:$E$833,C$1,Produccion_Semanal!$B$2:$B$833,$A3) -> 0.78941071 | D3: =SUMIFS(Produccion_Semanal!$S$2:$S$833,Produccion_Semanal!$E$2:$E$833,D$1,Produccion_Semanal!$B$2:$B$833,$A3) -> 0.77257675 | E3: =SUMIFS(Produccion_Semanal!$S$2:$S$833,Produccion_Semanal!$E$2:$E$833,E$1,Produccion_Semanal!$B$2:$B$833,$A3) -> 0.82688876 | F3: =SUMIFS(Produccion_Semanal!$S$2:$S$833,Produccion_Semanal!$E$2:$E$833,F$1,Produccion_Semanal!$B$2:$B$833,$A3) -> 0.75191571 | G3: =SUMIFS(Produccion_Semanal!$S$2:$S$833,Produccion_Semanal!$E$2:$E$833,G$1,Produccion_Semanal!$B$2:$B$833,$A3) -> 0.85075993 | H3: =SUMIFS(Produccion_Semanal!$S$2:$S$833,Produccion_Semanal!$E$2:$E$833,H$1,Produccion_Semanal!$B$2:$B$833,$A3) -> 0.63735515 | I3: =SUMIFS(Produccion_Semanal!$S$2:$S$833,Produccion_Semanal!$E$2:$E$833,I$1,Produccion_Semanal!$B$2:$B$833,$A3) -> 0.84639648
A4: 45565 | B4: =SUMIFS(Produccion_Semanal!$S$2:$S$833,Produccion_Semanal!$E$2:$E$833,B$1,Produccion_Semanal!$B$2:$B$833,$A4) -> 0.81309545 | C4: =SUMIFS(Produccion_Semanal!$S$2:$S$833,Produccion_Semanal!$E$2:$E$833,C$1,Produccion_Semanal!$B$2:$B$833,$A4) -> 0.8606717 | D4: =SUMIFS(Produccion_Semanal!$S$2:$S$833,Produccion_Semanal!$E$2:$E$833,D$1,Produccion_Semanal!$B$2:$B$833,$A4) -> 0.75976678 | E4: =SUMIFS(Produccion_Semanal!$S$2:$S$833,Produccion_Semanal!$E$2:$E$833,E$1,Produccion_Semanal!$B$2:$B$833,$A4) -> 0.81690247 | F4: =SUMIFS(Produccion_Semanal!$S$2:$S$833,Produccion_Semanal!$E$2:$E$833,F$1,Produccion_Semanal!$B$2:$B$833,$A4) -> 0.9084764 | G4: =SUMIFS(Produccion_Semanal!$S$2:$S$833,Produccion_Semanal!$E$2:$E$833,G$1,Produccion_Semanal!$B$2:$B$833,$A4) -> 0.82079673 | H4: =SUMIFS(Produccion_Semanal!$S$2:$S$833,Produccion_Semanal!$E$2:$E$833,H$1,Produccion_Semanal!$B$2:$B$833,$A4) -> 0.72399573 | I4: =SUMIFS(Produccion_Semanal!$S$2:$S$833,Produccion_Semanal!$E$2:$E$833,I$1,Produccion_Semanal!$B$2:$B$833,$A4) -> 0.87155337
A5: 45572 | B5: =SUMIFS(Produccion_Semanal!$S$2:$S$833,Produccion_Semanal!$E$2:$E$833,B$1,Produccion_Semanal!$B$2:$B$833,$A5) -> 0.82527513 | C5: =SUMIFS(Produccion_Semanal!$S$2:$S$833,Produccion_Semanal!$E$2:$E$833,C$1,Produccion_Semanal!$B$2:$B$833,$A5) -> 0.82599039 | D5: =SUMIFS(Produccion_Semanal!$S$2:$S$833,Produccion_Semanal!$E$2:$E$833,D$1,Produccion_Semanal!$B$2:$B$833,$A5) -> 0.79732523 | E5: =SUMIFS(Produccion_Semanal!$S$2:$S$833,Produccion_Semanal!$E$2:$E$833,E$1,Produccion_Semanal!$B$2:$B$833,$A5) -> 0.78977564 | F5: =SUMIFS(Produccion_Semanal!$S$2:$S$833,Produccion_Semanal!$E$2:$E$833,F$1,Produccion_Semanal!$B$2:$B$833,$A5) -> 0.79905836 | G5: =SUMIFS(Produccion_Semanal!$S$2:$S$833,Produccion_Semanal!$E$2:$E$833,G$1,Produccion_Semanal!$B$2:$B$833,$A5) -> 0.80552965 | H5: =SUMIFS(Produccion_Semanal!$S$2:$S$833,Produccion_Semanal!$E$2:$E$833,H$1,Produccion_Semanal!$B$2:$B$833,$A5) -> 0.7359169 | I5: =SUMIFS(Produccion_Semanal!$S$2:$S$833,Produccion_Semanal!$E$2:$E$833,I$1,Produccion_Semanal!$B$2:$B$833,$A5) -> 0.81267488
A6: 45579 | B6: =SUMIFS(Produccion_Semanal!$S$2:$S$833,Produccion_Semanal!$E$2:$E$833,B$1,Produccion_Semanal!$B$2:$B$833,$A6) -> 0.81838367 | C6: =SUMIFS(Produccion_Semanal!$S$2:$S$833,Produccion_Semanal!$E$2:$E$833,C$1,Produccion_Semanal!$B$2:$B$833,$A6) -> 0.8111001 | D6: =SUMIFS(Produccion_Semanal!$S$2:$S$833,Produccion_Semanal!$E$2:$E$833,D$1,Produccion_Semanal!$B$2:$B$833,$A6) -> 0.77823427 | E6: =SUMIFS(Produccion_Semanal!$S$2:$S$833,Produccion_Semanal!$E$2:$E$833,E$1,Produccion_Semanal!$B$2:$B$833,$A6) -> 0.77033234 | F6: =SUMIFS(Produccion_Semanal!$S$2:$S$833,Produccion_Semanal!$E$2:$E$833,F$1,Produccion_Semanal!$B$2:$B$833,$A6) -> 0.72789111 | G6: =SUMIFS(Produccion_Semanal!$S$2:$S$833,Produccion_Semanal!$E$2:$E$833,G$1,Produccion_Semanal!$B$2:$B$833,$A6) -> 0.84469086 | H6: =SUMIFS(Produccion_Semanal!$S$2:$S$833,Produccion_Semanal!$E$2:$E$833,H$1,Produccion_Semanal!$B$2:$B$833,$A6) -> 0.66571969 | I6: =SUMIFS(Produccion_Semanal!$S$2:$S$833,Produccion_Semanal!$E$2:$E$833,I$1,Produccion_Semanal!$B$2:$B$833,$A6) -> 0.77097769
A7: 45586 | B7: =SUMIFS(Produccion_Semanal!$S$2:$S$833,Produccion_Semanal!$E$2:$E$833,B$1,Produccion_Semanal!$B$2:$B$833,$A7) -> 0.84179637 | C7: =SUMIFS(Produccion_Semanal!$S$2:$S$833,Produccion_Semanal!$E$2:$E$833,C$1,Produccion_Semanal!$B$2:$B$833,$A7) -> 0.78878299 | D7: =SUMIFS(Produccion_Semanal!$S$2:$S$833,Produccion_Semanal!$E$2:$E$833,D$1,Produccion_Semanal!$B$2:$B$833,$A7) -> 0.7299764 | E7: =SUMIFS(Produccion_Semanal!$S$2:$S$833,Produccion_Semanal!$E$2:$E$833,E$1,Produccion_Semanal!$B$2:$B$833,$A7) -> 0.76467949 | F7: =SUMIFS(Produccion_Semanal!$S$2:$S$833,Produccion_Semanal!$E$2:$E$833,F$1,Produccion_Semanal!$B$2:$B$833,$A7) -> 0.66857637 | G7: =SUMIFS(Produccion_Semanal!$S$2:$S$833,Produccion_Semanal!$E$2:$E$833,G$1,Produccion_Semanal!$B$2:$B$833,$A7) -> 0.83400632 | H7: =SUMIFS(Produccion_Semanal!$S$2:$S$833,Produccion_Semanal!$E$2:$E$833,H$1,Produccion_Semanal!$B$2:$B$833,$A7) -> 0.66711955 | I7: =SUMIFS(Produccion_Semanal!$S$2:$S$833,Produccion_Semanal!$E$2:$E$833,I$1,Produccion_Semanal!$B$2:$B$833,$A7) -> 0.81090807
A8: 45593 | B8: =SUMIFS(Produccion_Semanal!$S$2:$S$833,Produccion_Semanal!$E$2:$E$833,B$1,Produccion_Semanal!$B$2:$B$833,$A8) -> 0.84058867 | C8: =SUMIFS(Produccion_Semanal!$S$2:$S$833,Produccion_Semanal!$E$2:$E$833,C$1,Produccion_Semanal!$B$2:$B$833,$A8) -> 0.82194783 | D8: =SUMIFS(Produccion_Semanal!$S$2:$S$833,Produccion_Semanal!$E$2:$E$833,D$1,Produccion_Semanal!$B$2:$B$833,$A8) -> 0.84206204 | E8: =SUMIFS(Produccion_Semanal!$S$2:$S$833,Produccion_Semanal!$E$2:$E$833,E$1,Produccion_Semanal!$B$2:$B$833,$A8) -> 0.77106521 | F8: =SUMIFS(Produccion_Semanal!$S$2:$S$833,Produccion_Semanal!$E$2:$E$833,F$1,Produccion_Semanal!$B$2:$B$833,$A8) -> 0.76972417 | G8: =SUMIFS(Produccion_Semanal!$S$2:$S$833,Produccion_Semanal!$E$2:$E$833,G$1,Produccion_Semanal!$B$2:$B$833,$A8) -> 0.85334315 | H8: =SUMIFS(Produccion_Semanal!$S$2:$S$833,Produccion_Semanal!$E$2:$E$833,H$1,Produccion_Semanal!$B$2:$B$833,$A8) -> 0.78941827 | I8: =SUMIFS(Produccion_Semanal!$S$2:$S$833,Produccion_Semanal!$E$2:$E$833,I$1,Produccion_Semanal!$B$2:$B$833,$A8) -> 0.81394647
A9: 45600 | B9: =SUMIFS(Produccion_Semanal!$S$2:$S$833,Produccion_Semanal!$E$2:$E$833,B$1,Produccion_Semanal!$B$2:$B$833,$A9) -> 0.84896433 | C9: =SUMIFS(Produccion_Semanal!$S$2:$S$833,Produccion_Semanal!$E$2:$E$833,C$1,Produccion_Semanal!$B$2:$B$833,$A9) -> 0.81128634 | D9: =SUMIFS(Produccion_Semanal!$S$2:$S$833,Produccion_Semanal!$E$2:$E$833,D$1,Produccion_Semanal!$B$2:$B$833,$A9) -> 0.78944083 | E9: =SUMIFS(Produccion_Semanal!$S$2:$S$833,Produccion_Semanal!$E$2:$E$833,E$1,Produccion_Semanal!$B$2:$B$833,$A9) -> 0.82009374 | F9: =SUMIFS(Produccion_Semanal!$S$2:$S$833,Produccion_Semanal!$E$2:$E$833,F$1,Produccion_Semanal!$B$2:$B$833,$A9) -> 0.76067559 | G9: =SUMIFS(Produccion_Semanal!$S$2:$S$833,Produccion_Semanal!$E$2:$E$833,G$1,Produccion_Semanal!$B$2:$B$833,$A9) -> 0.86621096 | H9: =SUMIFS(Produccion_Semanal!$S$2:$S$833,Produccion_Semanal!$E$2:$E$833,H$1,Produccion_Semanal!$B$2:$B$833,$A9) -> 0.61307422 | I9: =SUMIFS(Produccion_Semanal!$S$2:$S$833,Produccion_Semanal!$E$2:$E$833,I$1,Produccion_Semanal!$B$2:$B$833,$A9) -> 0.83179957
A10: 45607 | B10: =SUMIFS(Produccion_Semanal!$S$2:$S$833,Produccion_Semanal!$E$2:$E$833,B$1,Produccion_Semanal!$B$2:$B$833,$A10) -> 0.84292761 | C10: =SUMIFS(Produccion_Semanal!$S$2:$S$833,Produccion_Semanal!$E$2:$E$833,C$1,Produccion_Semanal!$B$2:$B$833,$A10) -> 0.84551325 | D10: =SUMIFS(Produccion_Semanal!$S$2:$S$833,Produccion_Semanal!$E$2:$E$833,D$1,Produccion_Semanal!$B$2:$B$833,$A10) -> 0.85033437 | E10: =SUMIFS(Produccion_Semanal!$S$2:$S$833,Produccion_Semanal!$E$2:$E$833,E$1,Produccion_Semanal!$B$2:$B$833,$A10) -> 0.74520612 | F10: =SUMIFS(Produccion_Semanal!$S$2:$S$833,Produccion_Semanal!$E$2:$E$833,F$1,Produccion_Semanal!$B$2:$B$833,$A10) -> 0.76914876 | G10: =SUMIFS(Produccion_Semanal!$S$2:$S$833,Produccion_Semanal!$E$2:$E$833,G$1,Produccion_Semanal!$B$2:$B$833,$A10) -> 0.8329932 | H10: =SUMIFS(Produccion_Semanal!$S$2:$S$833,Produccion_Semanal!$E$2:$E$833,H$1,Produccion_Semanal!$B$2:$B$833,$A10) -> 0.70027253 | I10: =SUMIFS(Produccion_Semanal!$S$2:$S$833,Produccion_Semanal!$E$2:$E$833,I$1,Produccion_Semanal!$B$2:$B$833,$A10) -> 0.74166204
